<?xml version="1.0" ?>
<robot name="jk_body" xmlns:xacro="http://ros.org/wiki/xacro">

	<!--
	<xacro:include filename="$(find jk_rollin_description)/urdf/common_properties.xacro"/>
	-->

	<xacro:macro name="jk_body">

	<link name="base_footprint"/>

	<joint name="base_joint" type="fixed">
		<parent link="base_footprint"/>
		<child link="base_link"/>
		<origin xyz="0.0 0.0 0.026" rpy="0 0 0"/>
	</joint>

	<link name="base_link">
		<visual>
			<origin xyz="0.0 0 -0.004" rpy="0 0 ${m_PI/2}"/>
			<geometry>
				<mesh filename="package://jk_rollin_description/meshes/bases/jk_rollin_body.stl" scale="0.001 0.001 0.001"/>
			</geometry>
			<material name="light_black"/>
		</visual>
		<visual>
			<origin xyz="-0.130 0 0.085" rpy="${m_PI/2} 0 ${-m_PI/2}"/>
			<geometry>
				<mesh filename="package://jk_rollin_description/meshes/bases/accu.stl" scale="0.001 0.001 0.001"/>
			</geometry>
			<material name="black"/>
		</visual>

		<collision>
			<origin xyz="-0.130 0.0 0.090" rpy="0 0 0"/>
			<geometry>
				<box size="0.115 0.075 0.060"/>
			</geometry>
		</collision>
		<collision>
			<origin xyz="-0.032 0 0.070" rpy="0 0 0"/>
			<geometry>
				<box size="0.010 0.010 0.010"/>
			</geometry>
		</collision>
		<collision>
			<origin xyz="-0.065 0.0 0.395" rpy="0 0 0"/>
			<geometry>
				<cylinder length="0.015" radius="0.05"/>
			</geometry>
		</collision>
		<collision>
			<origin xyz="0.0 0.0 0.03" rpy="0 0 0"/>
			<geometry>
				<cylinder length="0.02" radius="0.065"/>
			</geometry>
		</collision>
		<collision>
			<origin xyz="0.0 0.0 0.01" rpy="0 0 ${-m_PI/2}"/>
			<geometry>
				<mesh filename="package://jk_rollin_description/meshes/bases/collision_0.stl" scale="0.001 0.001 0.001"/>
			</geometry>
		</collision>


		<inertial>
			<origin xyz="-0.02 0 0" rpy="0 0 0"/>
			<mass value="2.998"/>
			<inertia ixx="44761.231e-06" ixy="-7.086e-06" ixz="-137.923e-06"
                                 iyy="41751.481e-06" iyz="-5503.844e-06"
                                 izz="20353.331e-06" />
		</inertial>
	</link>

	<joint name="wheel_left_joint" type="continuous">
		<parent link="base_link"/>
		<child link="wheel_left_link"/>
		<origin xyz="0.0 0.107 0.01425" rpy="${-m_PI/2} 0 0"/>
		<axis xyz="0 0 1"/>
		<limit effort="1000.0" velocity="3.0"/>
		<dynamics friction="1.0"/>
	</joint>

	<link name="wheel_left_link">
		<visual>
			<origin xyz="0 0 0" rpy="${m_PI/2} 0 0"/>
			<geometry>
				<mesh filename="package://jk_rollin_description/meshes/wheels/wheel.stl" scale="0.001 0.001 0.001"/>
			</geometry>
			<material name="dark"/>
		</visual>

		<collision>
			<origin xyz="0.0 0.0 +0.01" rpy="0 0 0"/>
			<geometry>
				<cylinder length="0.018" radius="0.041"/>
			</geometry>
		</collision>

		<inertial>
			<origin xyz="0 0 0" />
			<mass value="0.046" />
                        <inertia ixx="22.470e-06" ixy="0.0e-06" ixz="0.0e-06"
                                 iyy="43.413e-06" iyz="0.0e-06"
                                 izz="22.470e-06" />
		</inertial>
	</link>

	<joint name="wheel_right_joint" type="continuous">
		<parent link="base_link"/>
		<child link="wheel_right_link"/>
		<origin xyz="0.0 -0.107 0.01425" rpy="${-m_PI/2} 0 0"/>
		<axis xyz="0 0 1"/>
		<limit effort="1000.0" velocity="3.0"/>
		<dynamics friction="1.0"/>
	</joint>

	<link name="wheel_right_link">
		<visual>
			<origin xyz="0 0 0" rpy="${-m_PI/2} 0 0"/>
			<geometry>
				<mesh filename="package://jk_rollin_description/meshes/wheels/wheel.stl" scale="0.001 0.001 0.001"/>
			</geometry>
			<material name="dark"/>
		</visual>

		<collision>
			<origin xyz="0.0 0.0 -0.01" rpy="0 0 0"/>
			<geometry>
				<cylinder length="0.018" radius="0.041"/>
			</geometry>
		</collision>

		<inertial>
			<origin xyz="0 0 0" />
			<mass value="0.046" />
                        <inertia ixx="22.470e-06" ixy="0.0e-06" ixz="0.0e-06"
                                 iyy="43.413e-06" iyz="0.0e-06"
                                 izz="22.470e-06" />
		</inertial>
	</link>

	<joint name="caster_back_joint" type="fixed">
		<parent link="base_link"/>
		<child link="caster_back_link"/>
		<origin xyz="-0.110 0 -0.020" rpy="-1.57 0 0"/>
		<dynamics friction="0.0"/>
	</joint>

	<link name="caster_back_link">
		<collision>
			<origin xyz="0 0.001 0" rpy="0 0 0"/>
			<geometry>
				<box size="0.030 0.009 0.020"/>
			</geometry>
		</collision>

		<inertial>
			<origin xyz="0 0 0" />
			<mass value="0.005" />
			<inertia ixx="0.001" ixy="0.0" ixz="0.0"
				 iyy="0.001" iyz="0.0"
				izz="0.001" />
		</inertial>
	</link>


	<joint name="imu_joint" type="fixed">
		<parent link="base_link"/>
		<child link="imu_link"/>
		<origin xyz="-0.10 0 0.008" rpy="0 0 0"/>
	</joint>

	<link name="imu_link"/>

	</xacro:macro>

</robot>
